<robot
  name="Crawler_URDF_V2">
  <link
    name="chasis_link">
    <inertial>
      <origin
        xyz="7.7385E-18 -0.071811 0.062283"
        rpy="0 0 0" />
      <mass
        value="9.6395" />
      <inertia
        ixx="0.17511"
        ixy="-8.1044E-17"
        ixz="-8.3654E-18"
        iyy="0.12517"
        iyz="-0.0042749"
        izz="0.28007" />
    </inertial>
    <visual>
      <origin
        xyz="0 0 0"
        rpy="0 0 0" />
      <geometry>
        <mesh
          filename="package://Crawler_URDF_V2/meshes/chasis_link.STL" />
      </geometry>
      <material
        name="">
        <color
          rgba="1 0.5 0 1" />
      </material>
    </visual>
    <collision>
      <origin
        xyz="0 0 0"
        rpy="0 0 0" />
      <geometry>
        <mesh
          filename="package://Crawler_URDF_V2/meshes/chasis_link.STL" />
      </geometry>
    </collision>
  </link>
  <link
    name="trans_base_link">
    <inertial>
      <origin
        xyz="-1.2421E-17 0.011149 0.031201"
        rpy="0 0 0" />
      <mass
        value="1.5263" />
      <inertia
        ixx="0.0051588"
        ixy="-1.6241E-18"
        ixz="2.3966E-18"
        iyy="0.0054798"
        iyz="-0.00038436"
        izz="0.010072" />
    </inertial>
    <visual>
      <origin
        xyz="0 0 0"
        rpy="0 0 0" />
      <geometry>
        <mesh
          filename="package://Crawler_URDF_V2/meshes/trans_base_link.STL" />
      </geometry>
      <material
        name="">
        <color
          rgba="0.1 0.1 0.1 1" />
      </material>
    </visual>
    <collision>
      <origin
        xyz="0 0 0"
        rpy="0 0 0" />
      <geometry>
        <mesh
          filename="package://Crawler_URDF_V2/meshes/trans_base_link.STL" />
      </geometry>
    </collision>
  </link>
  <joint
    name="trans_base_joint"
    type="prismatic">
    <origin
      xyz="0 0 0"
      rpy="0 0 0" />
    <parent
      link="chasis_link" />
    <child
      link="trans_base_link" />
    <axis
      xyz="0 1 0" />
    <limit
      effort="0"
      velocity="0" />
  </joint>
  <link
    name="arm_yaw_link">
    <inertial>
      <origin
        xyz="-0.0021254 -0.0006114 0.032239"
        rpy="0 0 0" />
      <mass
        value="0.3618" />
      <inertia
        ixx="0.00032781"
        ixy="4.7945E-06"
        ixz="2.6885E-05"
        iyy="0.00034998"
        iyz="-4.7052E-06"
        izz="0.00043771" />
    </inertial>
    <visual>
      <origin
        xyz="0 0 0"
        rpy="0 0 0" />
      <geometry>
        <mesh
          filename="package://Crawler_URDF_V2/meshes/arm_yaw_link.STL" />
      </geometry>
      <material
        name="">
        <color
          rgba="0.5 0.5 0.5 1" />
      </material>
    </visual>
    <collision>
      <origin
        xyz="0 0 0"
        rpy="0 0 0" />
      <geometry>
        <mesh
          filename="package://Crawler_URDF_V2/meshes/arm_yaw_link.STL" />
      </geometry>
    </collision>
  </link>
  <joint
    name="Arm_yaw_joint"
    type="revolute">
    <origin
      xyz="0 0.0895 0.035016"
      rpy="0 0 0" />
    <parent
      link="trans_base_link" />
    <child
      link="arm_yaw_link" />
    <axis
      xyz="0 0 -1" />
    <limit
      effort="0"
      velocity="0" />
  </joint>
  <link
    name="arm_pitch_link">
    <inertial>
      <origin
        xyz="0.058958 -0.14006 0.0019553"
        rpy="0 0 0" />
      <mass
        value="1.8549" />
      <inertia
        ixx="0.025771"
        ixy="-0.00043969"
        ixz="2.1292E-05"
        iyy="0.0039261"
        iyz="-6.5767E-05"
        izz="0.022366" />
    </inertial>
    <visual>
      <origin
        xyz="0 0 0"
        rpy="0 0 0" />
      <geometry>
        <mesh
          filename="package://Crawler_URDF_V2/meshes/arm_pitch_link.STL" />
      </geometry>
      <material
        name="">
        <color
          rgba="0.1 0.1 0.1 1" />
      </material>
    </visual>
    <collision>
      <origin
        xyz="0 0 0"
        rpy="0 0 0" />
      <geometry>
        <mesh
          filename="package://Crawler_URDF_V2/meshes/arm_pitch_link.STL" />
      </geometry>
    </collision>
  </link>
  <joint
    name="arm_pitch_joint"
    type="revolute">
    <origin
      xyz="-0.0015 0 0.043"
      rpy="3.1416 -1.5708 0" />
    <parent
      link="arm_yaw_link" />
    <child
      link="arm_pitch_link" />
    <axis
      xyz="0 0 -1" />
    <limit
      effort="0"
      velocity="0" />
  </joint>
  <link
    name="arm_prismatic_link">
    <inertial>
      <origin
        xyz="0.0010163 -0.17913 4.2394E-13"
        rpy="0 0 0" />
      <mass
        value="0.11002" />
      <inertia
        ixx="0.0012634"
        ixy="-1.3841E-06"
        ixz="-2.1069E-16"
        iyy="7.2304E-06"
        iyz="2.9808E-15"
        izz="0.0012609" />
    </inertial>
    <visual>
      <origin
        xyz="0 0 0"
        rpy="0 0 0" />
      <geometry>
        <mesh
          filename="package://Crawler_URDF_V2/meshes/arm_prismatic_link.STL" />
      </geometry>
      <material
        name="">
        <color
          rgba="0.1 0.1 0.1 1" />
      </material>
    </visual>
    <collision>
      <origin
        xyz="0 0 0"
        rpy="0 0 0" />
      <geometry>
        <mesh
          filename="package://Crawler_URDF_V2/meshes/arm_prismatic_link.STL" />
      </geometry>
    </collision>
  </link>
  <joint
    name="arm_prismatic_joint"
    type="prismatic">
    <origin
      xyz="0.063769 0.09977 -0.0015"
      rpy="-4.1085E-48 -6.1428E-48 2.5238E-95" />
    <parent
      link="arm_pitch_link" />
    <child
      link="arm_prismatic_link" />
    <axis
      xyz="0 -1 0" />
    <limit
      effort="0"
      velocity="0" />
  </joint>
  <link
    name="wrist_pitch_link">
    <inertial>
      <origin
        xyz="-0.00015791 0.0064779 -1.0787E-10"
        rpy="0 0 0" />
      <mass
        value="0.0052835" />
      <inertia
        ixx="3.4106E-07"
        ixy="-5.1912E-09"
        ixz="4.1187E-15"
        iyy="2.6131E-07"
        iyz="5.3377E-15"
        izz="3.7182E-07" />
    </inertial>
    <visual>
      <origin
        xyz="0 0 0"
        rpy="0 0 0" />
      <geometry>
        <mesh
          filename="package://Crawler_URDF_V2/meshes/wrist_pitch_link.STL" />
      </geometry>
      <material
        name="">
        <color
          rgba="0.9 0.9 0.9 1" />
      </material>
    </visual>
    <collision>
      <origin
        xyz="0 0 0"
        rpy="0 0 0" />
      <geometry>
        <mesh
          filename="package://Crawler_URDF_V2/meshes/wrist_pitch_link.STL" />
      </geometry>
    </collision>
  </link>
  <joint
    name="wrist_pitch_joint"
    type="revolute">
    <origin
      xyz="0 0 0"
      rpy="-3.6047E-16 1.8276E-16 0.7854" />
    <parent
      link="arm_prismatic_link" />
    <child
      link="wrist_pitch_link" />
    <axis
      xyz="0 0 1" />
    <limit
      effort="0"
      velocity="0" />
  </joint>
  <link
    name="wrist_roll_link">
    <inertial>
      <origin
        xyz="-8.1101E-13 0.017665 -0.059822"
        rpy="0 0 0" />
      <mass
        value="0.99835" />
      <inertia
        ixx="0.0017542"
        ixy="1.9545E-11"
        ixz="1.1324E-11"
        iyy="0.0016174"
        iyz="4.9729E-05"
        izz="0.0015951" />
    </inertial>
    <visual>
      <origin
        xyz="0 0 0"
        rpy="0 0 0" />
      <geometry>
        <mesh
          filename="package://Crawler_URDF_V2/meshes/wrist_roll_link.STL" />
      </geometry>
      <material
        name="">
        <color
          rgba="0.79216 0.81961 0.93333 1" />
      </material>
    </visual>
    <collision>
      <origin
        xyz="0 0 0"
        rpy="0 0 0" />
      <geometry>
        <mesh
          filename="package://Crawler_URDF_V2/meshes/wrist_roll_link.STL" />
      </geometry>
    </collision>
  </link>
  <joint
    name="wrist_roll_joint"
    type="revolute">
    <origin
      xyz="0 0.0127 0"
      rpy="1.0472 1.5708 0" />
    <parent
      link="wrist_pitch_link" />
    <child
      link="wrist_roll_link" />
    <axis
      xyz="0 0.86603 0.5" />
    <limit
      lower="-0.5236"
      upper="0.5236"
      effort="0"
      velocity="0" />
  </joint>
  <link
    name="tool_link">
    <inertial>
      <origin
        xyz="-7.9147E-13 -0.016676 0.078258"
        rpy="0 0 0" />
      <mass
        value="0.99916" />
      <inertia
        ixx="0.0017579"
        ixy="2.2588E-11"
        ixz="3.4406E-14"
        iyy="0.0015723"
        iyz="3.367E-05"
        izz="0.0016439" />
    </inertial>
    <visual>
      <origin
        xyz="0 0 0"
        rpy="0 0 0" />
      <geometry>
        <mesh
          filename="package://Crawler_URDF_V2/meshes/tool_link.STL" />
      </geometry>
      <material
        name="">
        <color
          rgba="1 0 0 1" />
      </material>
    </visual>
    <collision>
      <origin
        xyz="0 0 0"
        rpy="0 0 0" />
      <geometry>
        <mesh
          filename="package://Crawler_URDF_V2/meshes/tool_link.STL" />
      </geometry>
    </collision>
  </link>
  <joint
    name="tool_joint"
    type="fixed">
    <origin
      xyz="0 0.071274 -0.1193"
      rpy="0.5236 2.5158E-13 -4.363E-13" />
    <parent
      link="wrist_roll_link" />
    <child
      link="tool_link" />
    <axis
      xyz="0 0 0" />
  </joint>
  <link
    name="cmass_left_link">
    <inertial>
      <origin
        xyz="-0.168 -0.0037764 0.0655"
        rpy="0 0 0" />
      <mass
        value="0.5444" />
      <inertia
        ixx="0.0096631"
        ixy="-1.3919E-17"
        ixz="-5.7038E-20"
        iyy="0.00044888"
        iyz="1.6001E-18"
        izz="0.0092273" />
    </inertial>
    <visual>
      <origin
        xyz="0 0 0"
        rpy="0 0 0" />
      <geometry>
        <mesh
          filename="package://Crawler_URDF_V2/meshes/cmass_left_link.STL" />
      </geometry>
      <material
        name="">
        <color
          rgba="0.1 0.1 0.1 1" />
      </material>
    </visual>
    <collision>
      <origin
        xyz="0 0 0"
        rpy="0 0 0" />
      <geometry>
        <mesh
          filename="package://Crawler_URDF_V2/meshes/cmass_left_link.STL" />
      </geometry>
    </collision>
  </link>
  <joint
    name="cmass_left_joint"
    type="prismatic">
    <origin
      xyz="0.002 0 -0.015"
      rpy="0 0 0" />
    <parent
      link="chasis_link" />
    <child
      link="cmass_left_link" />
    <axis
      xyz="0 1 0" />
    <limit
      effort="0"
      velocity="0" />
  </joint>
  <link
    name="cmass_right_link">
    <inertial>
      <origin
        xyz="0.168 -0.0037764 0.0655"
        rpy="0 0 0" />
      <mass
        value="0.5444" />
      <inertia
        ixx="0.0096631"
        ixy="1.2622E-17"
        ixz="-7.2733E-20"
        iyy="0.00044888"
        iyz="7.3547E-19"
        izz="0.0092273" />
    </inertial>
    <visual>
      <origin
        xyz="0 0 0"
        rpy="0 0 0" />
      <geometry>
        <mesh
          filename="package://Crawler_URDF_V2/meshes/cmass_right_link.STL" />
      </geometry>
      <material
        name="">
        <color
          rgba="0.1 0.1 0.1 1" />
      </material>
    </visual>
    <collision>
      <origin
        xyz="0 0 0"
        rpy="0 0 0" />
      <geometry>
        <mesh
          filename="package://Crawler_URDF_V2/meshes/cmass_right_link.STL" />
      </geometry>
    </collision>
  </link>
  <joint
    name="cmass_right_joint"
    type="prismatic">
    <origin
      xyz="-0.002 0 -0.015"
      rpy="0 0 0" />
    <parent
      link="chasis_link" />
    <child
      link="cmass_right_link" />
    <axis
      xyz="0 -1 0" />
    <limit
      effort="0"
      velocity="0" />
  </joint>
</robot>